2025-03-17 14:26:05,465 - __main__ - INFO - MongoDB connection established successfully
2025-03-17 14:26:05,666 - __main__ - INFO - Model loaded successfully
2025-03-17 14:26:05,666 - __main__ - INFO - Scaler loaded successfully
2025-03-17 14:26:05,666 - __main__ - INFO - Label encoder loaded successfully
2025-03-17 14:26:05,672 - __main__ - INFO - Starting prediction service on http://localhost:5000
2025-03-17 14:26:05,688 - werkzeug - INFO - [31m[1mWARNING: This is a development server. Do not use it in a production deployment. Use a production WSGI server instead.[0m
 * Running on all addresses (0.0.0.0)
 * Running on http://127.0.0.1:5000
 * Running on http://172.28.4.140:5000
2025-03-17 14:26:05,688 - werkzeug - INFO - [33mPress CTRL+C to quit[0m
2025-03-17 14:26:09,838 - __main__ - WARNING - Failed to retrieve dataset size: Collection objects do not implement truth value testing or bool(). Please compare with None instead: collection is not None
2025-03-17 14:26:09,840 - __main__ - ERROR - Error in calculate_performance_metrics_from_recent_data: Collection objects do not implement truth value testing or bool(). Please compare with None instead: collection is not None
2025-03-17 14:26:09,841 - werkzeug - INFO - 127.0.0.1 - - [17/Mar/2025 14:26:09] "GET /api/dashboard/model-metrics HTTP/1.1" 200 -
2025-03-17 14:26:09,848 - __main__ - INFO - No training_params.json file found, using default values
2025-03-17 14:26:09,860 - __main__ - ERROR - Unhandled error in get_model_config: Object of type int64 is not JSON serializable
Traceback (most recent call last):
  File "D:\research\adhd-assessment-system\backend\mlmodels\it21288326\retrain_model.py", line 2351, in get_model_config
    return jsonify(response), 200
           ^^^^^^^^^^^^^^^^^
  File "D:\research\adhd-assessment-system\backend\mlmodels\it21288326\venv\Lib\site-packages\flask\json\__init__.py", line 170, in jsonify
    return current_app.json.response(*args, **kwargs)  # type: ignore[return-value]
           ^^^^^^^^^^^^^^^^^^^^^^^^^^^^^^^^^^^^^^^^^^
  File "D:\research\adhd-assessment-system\backend\mlmodels\it21288326\venv\Lib\site-packages\flask\json\provider.py", line 214, in response
    f"{self.dumps(obj, **dump_args)}\n", mimetype=self.mimetype
       ^^^^^^^^^^^^^^^^^^^^^^^^^^^^
  File "D:\research\adhd-assessment-system\backend\mlmodels\it21288326\venv\Lib\site-packages\flask\json\provider.py", line 179, in dumps
    return json.dumps(obj, **kwargs)
           ^^^^^^^^^^^^^^^^^^^^^^^^^
  File "C:\Users\User\AppData\Local\Programs\Python\Python311\Lib\json\__init__.py", line 238, in dumps
    **kw).encode(obj)
          ^^^^^^^^^^^
  File "C:\Users\User\AppData\Local\Programs\Python\Python311\Lib\json\encoder.py", line 200, in encode
    chunks = self.iterencode(o, _one_shot=True)
             ^^^^^^^^^^^^^^^^^^^^^^^^^^^^^^^^^^
  File "C:\Users\User\AppData\Local\Programs\Python\Python311\Lib\json\encoder.py", line 258, in iterencode
    return _iterencode(o, 0)
           ^^^^^^^^^^^^^^^^^
  File "D:\research\adhd-assessment-system\backend\mlmodels\it21288326\venv\Lib\site-packages\flask\json\provider.py", line 121, in _default
    raise TypeError(f"Object of type {type(o).__name__} is not JSON serializable")
TypeError: Object of type int64 is not JSON serializable

2025-03-17 14:26:09,861 - werkzeug - INFO - 127.0.0.1 - - [17/Mar/2025 14:26:09] "[35m[1mGET /api/dashboard/model-config HTTP/1.1[0m" 500 -
2025-03-17 14:26:10,132 - werkzeug - INFO - 127.0.0.1 - - [17/Mar/2025 14:26:10] "GET /api/dashboard/system-status HTTP/1.1" 200 -
2025-03-17 14:26:11,793 - werkzeug - INFO - 127.0.0.1 - - [17/Mar/2025 14:26:11] "GET /api/dashboard/prediction-metrics HTTP/1.1" 200 -
2025-03-17 14:26:12,729 - werkzeug - INFO - 127.0.0.1 - - [17/Mar/2025 14:26:12] "GET /api/dashboard/assessment-stats HTTP/1.1" 200 -
2025-03-17 14:26:15,296 - werkzeug - INFO - 127.0.0.1 - - [17/Mar/2025 14:26:15] "GET /api/dashboard/system-status HTTP/1.1" 200 -
2025-03-17 14:26:15,360 - __main__ - WARNING - Failed to retrieve dataset size: Collection objects do not implement truth value testing or bool(). Please compare with None instead: collection is not None
2025-03-17 14:26:15,360 - __main__ - ERROR - Error in calculate_performance_metrics_from_recent_data: Collection objects do not implement truth value testing or bool(). Please compare with None instead: collection is not None
2025-03-17 14:26:15,375 - werkzeug - INFO - 127.0.0.1 - - [17/Mar/2025 14:26:15] "GET /api/dashboard/model-metrics HTTP/1.1" 200 -
2025-03-17 14:26:15,375 - __main__ - INFO - No training_params.json file found, using default values
2025-03-17 14:26:15,385 - __main__ - ERROR - Unhandled error in get_model_config: Object of type int64 is not JSON serializable
Traceback (most recent call last):
  File "D:\research\adhd-assessment-system\backend\mlmodels\it21288326\retrain_model.py", line 2351, in get_model_config
    return jsonify(response), 200
           ^^^^^^^^^^^^^^^^^
  File "D:\research\adhd-assessment-system\backend\mlmodels\it21288326\venv\Lib\site-packages\flask\json\__init__.py", line 170, in jsonify
    return current_app.json.response(*args, **kwargs)  # type: ignore[return-value]
           ^^^^^^^^^^^^^^^^^^^^^^^^^^^^^^^^^^^^^^^^^^
  File "D:\research\adhd-assessment-system\backend\mlmodels\it21288326\venv\Lib\site-packages\flask\json\provider.py", line 214, in response
    f"{self.dumps(obj, **dump_args)}\n", mimetype=self.mimetype
       ^^^^^^^^^^^^^^^^^^^^^^^^^^^^
  File "D:\research\adhd-assessment-system\backend\mlmodels\it21288326\venv\Lib\site-packages\flask\json\provider.py", line 179, in dumps
    return json.dumps(obj, **kwargs)
           ^^^^^^^^^^^^^^^^^^^^^^^^^
  File "C:\Users\User\AppData\Local\Programs\Python\Python311\Lib\json\__init__.py", line 238, in dumps
    **kw).encode(obj)
          ^^^^^^^^^^^
  File "C:\Users\User\AppData\Local\Programs\Python\Python311\Lib\json\encoder.py", line 200, in encode
    chunks = self.iterencode(o, _one_shot=True)
             ^^^^^^^^^^^^^^^^^^^^^^^^^^^^^^^^^^
  File "C:\Users\User\AppData\Local\Programs\Python\Python311\Lib\json\encoder.py", line 258, in iterencode
    return _iterencode(o, 0)
           ^^^^^^^^^^^^^^^^^
  File "D:\research\adhd-assessment-system\backend\mlmodels\it21288326\venv\Lib\site-packages\flask\json\provider.py", line 121, in _default
    raise TypeError(f"Object of type {type(o).__name__} is not JSON serializable")
TypeError: Object of type int64 is not JSON serializable

2025-03-17 14:26:15,391 - werkzeug - INFO - 127.0.0.1 - - [17/Mar/2025 14:26:15] "[35m[1mGET /api/dashboard/model-config HTTP/1.1[0m" 500 -
2025-03-17 14:26:15,693 - __main__ - WARNING - Failed to retrieve dataset size: Collection objects do not implement truth value testing or bool(). Please compare with None instead: collection is not None
2025-03-17 14:26:15,693 - __main__ - ERROR - Error in calculate_performance_metrics_from_recent_data: Collection objects do not implement truth value testing or bool(). Please compare with None instead: collection is not None
2025-03-17 14:26:15,700 - werkzeug - INFO - 127.0.0.1 - - [17/Mar/2025 14:26:15] "GET /api/dashboard/model-metrics HTTP/1.1" 200 -
2025-03-17 14:26:15,702 - __main__ - INFO - No training_params.json file found, using default values
2025-03-17 14:26:15,709 - __main__ - ERROR - Unhandled error in get_model_config: Object of type int64 is not JSON serializable
Traceback (most recent call last):
  File "D:\research\adhd-assessment-system\backend\mlmodels\it21288326\retrain_model.py", line 2351, in get_model_config
    return jsonify(response), 200
           ^^^^^^^^^^^^^^^^^
  File "D:\research\adhd-assessment-system\backend\mlmodels\it21288326\venv\Lib\site-packages\flask\json\__init__.py", line 170, in jsonify
    return current_app.json.response(*args, **kwargs)  # type: ignore[return-value]
           ^^^^^^^^^^^^^^^^^^^^^^^^^^^^^^^^^^^^^^^^^^
  File "D:\research\adhd-assessment-system\backend\mlmodels\it21288326\venv\Lib\site-packages\flask\json\provider.py", line 214, in response
    f"{self.dumps(obj, **dump_args)}\n", mimetype=self.mimetype
       ^^^^^^^^^^^^^^^^^^^^^^^^^^^^
  File "D:\research\adhd-assessment-system\backend\mlmodels\it21288326\venv\Lib\site-packages\flask\json\provider.py", line 179, in dumps
    return json.dumps(obj, **kwargs)
           ^^^^^^^^^^^^^^^^^^^^^^^^^
  File "C:\Users\User\AppData\Local\Programs\Python\Python311\Lib\json\__init__.py", line 238, in dumps
    **kw).encode(obj)
          ^^^^^^^^^^^
  File "C:\Users\User\AppData\Local\Programs\Python\Python311\Lib\json\encoder.py", line 200, in encode
    chunks = self.iterencode(o, _one_shot=True)
             ^^^^^^^^^^^^^^^^^^^^^^^^^^^^^^^^^^
  File "C:\Users\User\AppData\Local\Programs\Python\Python311\Lib\json\encoder.py", line 258, in iterencode
    return _iterencode(o, 0)
           ^^^^^^^^^^^^^^^^^
  File "D:\research\adhd-assessment-system\backend\mlmodels\it21288326\venv\Lib\site-packages\flask\json\provider.py", line 121, in _default
    raise TypeError(f"Object of type {type(o).__name__} is not JSON serializable")
TypeError: Object of type int64 is not JSON serializable

2025-03-17 14:26:15,709 - werkzeug - INFO - 127.0.0.1 - - [17/Mar/2025 14:26:15] "[35m[1mGET /api/dashboard/model-config HTTP/1.1[0m" 500 -
2025-03-17 14:26:15,789 - werkzeug - INFO - 127.0.0.1 - - [17/Mar/2025 14:26:15] "GET /api/dashboard/prediction-metrics HTTP/1.1" 200 -
2025-03-17 14:26:15,825 - werkzeug - INFO - 127.0.0.1 - - [17/Mar/2025 14:26:15] "GET /api/dashboard/system-status HTTP/1.1" 200 -
2025-03-17 14:26:16,427 - werkzeug - INFO - 127.0.0.1 - - [17/Mar/2025 14:26:16] "GET /api/dashboard/prediction-metrics HTTP/1.1" 200 -
2025-03-17 14:26:16,429 - werkzeug - INFO - 127.0.0.1 - - [17/Mar/2025 14:26:16] "GET /api/dashboard/assessment-stats HTTP/1.1" 200 -
2025-03-17 14:26:17,855 - werkzeug - INFO - 127.0.0.1 - - [17/Mar/2025 14:26:17] "GET /api/dashboard/assessment-stats HTTP/1.1" 200 -
2025-03-17 14:32:21,876 - __main__ - WARNING - Failed to retrieve dataset size: Collection objects do not implement truth value testing or bool(). Please compare with None instead: collection is not None
2025-03-17 14:32:21,876 - __main__ - ERROR - Error in calculate_performance_metrics_from_recent_data: Collection objects do not implement truth value testing or bool(). Please compare with None instead: collection is not None
2025-03-17 14:32:21,886 - werkzeug - INFO - 127.0.0.1 - - [17/Mar/2025 14:32:21] "GET /api/dashboard/model-metrics HTTP/1.1" 200 -
2025-03-17 14:32:21,886 - __main__ - INFO - No training_params.json file found, using default values
2025-03-17 14:32:21,955 - __main__ - ERROR - Unhandled error in get_model_config: Object of type int64 is not JSON serializable
Traceback (most recent call last):
  File "D:\research\adhd-assessment-system\backend\mlmodels\it21288326\retrain_model.py", line 2351, in get_model_config
    return jsonify(response), 200
           ^^^^^^^^^^^^^^^^^
  File "D:\research\adhd-assessment-system\backend\mlmodels\it21288326\venv\Lib\site-packages\flask\json\__init__.py", line 170, in jsonify
    return current_app.json.response(*args, **kwargs)  # type: ignore[return-value]
           ^^^^^^^^^^^^^^^^^^^^^^^^^^^^^^^^^^^^^^^^^^
  File "D:\research\adhd-assessment-system\backend\mlmodels\it21288326\venv\Lib\site-packages\flask\json\provider.py", line 214, in response
    f"{self.dumps(obj, **dump_args)}\n", mimetype=self.mimetype
       ^^^^^^^^^^^^^^^^^^^^^^^^^^^^
  File "D:\research\adhd-assessment-system\backend\mlmodels\it21288326\venv\Lib\site-packages\flask\json\provider.py", line 179, in dumps
    return json.dumps(obj, **kwargs)
           ^^^^^^^^^^^^^^^^^^^^^^^^^
  File "C:\Users\User\AppData\Local\Programs\Python\Python311\Lib\json\__init__.py", line 238, in dumps
    **kw).encode(obj)
          ^^^^^^^^^^^
  File "C:\Users\User\AppData\Local\Programs\Python\Python311\Lib\json\encoder.py", line 200, in encode
    chunks = self.iterencode(o, _one_shot=True)
             ^^^^^^^^^^^^^^^^^^^^^^^^^^^^^^^^^^
  File "C:\Users\User\AppData\Local\Programs\Python\Python311\Lib\json\encoder.py", line 258, in iterencode
    return _iterencode(o, 0)
           ^^^^^^^^^^^^^^^^^
  File "D:\research\adhd-assessment-system\backend\mlmodels\it21288326\venv\Lib\site-packages\flask\json\provider.py", line 121, in _default
    raise TypeError(f"Object of type {type(o).__name__} is not JSON serializable")
TypeError: Object of type int64 is not JSON serializable

2025-03-17 14:32:21,955 - werkzeug - INFO - 127.0.0.1 - - [17/Mar/2025 14:32:21] "[35m[1mGET /api/dashboard/model-config HTTP/1.1[0m" 500 -
2025-03-17 14:32:22,018 - werkzeug - INFO - 127.0.0.1 - - [17/Mar/2025 14:32:22] "GET /api/dashboard/system-status HTTP/1.1" 200 -
2025-03-17 14:32:22,226 - werkzeug - INFO - 127.0.0.1 - - [17/Mar/2025 14:32:22] "GET /api/dashboard/prediction-metrics HTTP/1.1" 200 -
2025-03-17 14:32:22,952 - werkzeug - INFO - 127.0.0.1 - - [17/Mar/2025 14:32:22] "GET /api/dashboard/assessment-stats HTTP/1.1" 200 -
2025-03-17 14:37:39,162 - __main__ - INFO - MongoDB connection established successfully
2025-03-17 14:37:39,344 - __main__ - INFO - Model loaded successfully
2025-03-17 14:37:39,347 - __main__ - INFO - Scaler loaded successfully
2025-03-17 14:37:39,347 - __main__ - INFO - Label encoder loaded successfully
2025-03-17 14:37:39,347 - __main__ - INFO - Starting prediction service on http://localhost:5000
2025-03-17 14:37:39,361 - werkzeug - INFO - [31m[1mWARNING: This is a development server. Do not use it in a production deployment. Use a production WSGI server instead.[0m
 * Running on all addresses (0.0.0.0)
 * Running on http://127.0.0.1:5000
 * Running on http://172.28.4.140:5000
2025-03-17 14:37:39,361 - werkzeug - INFO - [33mPress CTRL+C to quit[0m
2025-03-17 14:37:48,800 - __main__ - WARNING - Failed to retrieve dataset size: Collection objects do not implement truth value testing or bool(). Please compare with None instead: collection is not None
2025-03-17 14:37:48,800 - __main__ - ERROR - Error in calculate_performance_metrics_from_recent_data: Collection objects do not implement truth value testing or bool(). Please compare with None instead: collection is not None
2025-03-17 14:37:48,811 - werkzeug - INFO - 127.0.0.1 - - [17/Mar/2025 14:37:48] "GET /api/dashboard/model-metrics HTTP/1.1" 200 -
2025-03-17 14:37:48,811 - __main__ - INFO - No training_params.json file found, using default values
2025-03-17 14:37:48,811 - retrain_model - ERROR - Exception on /api/dashboard/model-config [GET]
Traceback (most recent call last):
  File "D:\research\adhd-assessment-system\backend\mlmodels\it21288326\venv\Lib\site-packages\flask\app.py", line 1511, in wsgi_app
    response = self.full_dispatch_request()
               ^^^^^^^^^^^^^^^^^^^^^^^^^^^^
  File "D:\research\adhd-assessment-system\backend\mlmodels\it21288326\venv\Lib\site-packages\flask\app.py", line 919, in full_dispatch_request
    rv = self.handle_user_exception(e)
         ^^^^^^^^^^^^^^^^^^^^^^^^^^^^^
  File "D:\research\adhd-assessment-system\backend\mlmodels\it21288326\venv\Lib\site-packages\flask_cors\extension.py", line 176, in wrapped_function
    return cors_after_request(app.make_response(f(*args, **kwargs)))
                                                ^^^^^^^^^^^^^^^^^^
  File "D:\research\adhd-assessment-system\backend\mlmodels\it21288326\venv\Lib\site-packages\flask\app.py", line 917, in full_dispatch_request
    rv = self.dispatch_request()
         ^^^^^^^^^^^^^^^^^^^^^^^
  File "D:\research\adhd-assessment-system\backend\mlmodels\it21288326\venv\Lib\site-packages\flask\app.py", line 902, in dispatch_request
    return self.ensure_sync(self.view_functions[rule.endpoint])(**view_args)  # type: ignore[no-any-return]
           ^^^^^^^^^^^^^^^^^^^^^^^^^^^^^^^^^^^^^^^^^^^^^^^^^^^^^^^^^^^^^^^^^
  File "D:\research\adhd-assessment-system\backend\mlmodels\it21288326\retrain_model.py", line 2393, in get_model_config
    "timestamp": datetime.datetime.now().isoformat()
                 ^^^^^^^^^^^^^^^^^
AttributeError: type object 'datetime.datetime' has no attribute 'datetime'
2025-03-17 14:37:48,827 - werkzeug - INFO - 127.0.0.1 - - [17/Mar/2025 14:37:48] "[35m[1mGET /api/dashboard/model-config HTTP/1.1[0m" 500 -
2025-03-17 14:37:49,052 - werkzeug - INFO - 127.0.0.1 - - [17/Mar/2025 14:37:49] "GET /api/dashboard/system-status HTTP/1.1" 200 -
2025-03-17 14:37:51,112 - werkzeug - INFO - 127.0.0.1 - - [17/Mar/2025 14:37:51] "GET /api/dashboard/prediction-metrics HTTP/1.1" 200 -
2025-03-17 14:37:51,707 - werkzeug - INFO - 127.0.0.1 - - [17/Mar/2025 14:37:51] "GET /api/dashboard/assessment-stats HTTP/1.1" 200 -
2025-03-17 14:37:53,659 - werkzeug - INFO - 127.0.0.1 - - [17/Mar/2025 14:37:53] "GET /api/dashboard/system-status HTTP/1.1" 200 -
2025-03-17 14:37:53,841 - __main__ - WARNING - Failed to retrieve dataset size: Collection objects do not implement truth value testing or bool(). Please compare with None instead: collection is not None
2025-03-17 14:37:53,843 - __main__ - ERROR - Error in calculate_performance_metrics_from_recent_data: Collection objects do not implement truth value testing or bool(). Please compare with None instead: collection is not None
2025-03-17 14:37:53,845 - __main__ - INFO - No training_params.json file found, using default values
2025-03-17 14:37:53,847 - werkzeug - INFO - 127.0.0.1 - - [17/Mar/2025 14:37:53] "GET /api/dashboard/model-metrics HTTP/1.1" 200 -
2025-03-17 14:37:53,847 - retrain_model - ERROR - Exception on /api/dashboard/model-config [GET]
Traceback (most recent call last):
  File "D:\research\adhd-assessment-system\backend\mlmodels\it21288326\venv\Lib\site-packages\flask\app.py", line 1511, in wsgi_app
    response = self.full_dispatch_request()
               ^^^^^^^^^^^^^^^^^^^^^^^^^^^^
  File "D:\research\adhd-assessment-system\backend\mlmodels\it21288326\venv\Lib\site-packages\flask\app.py", line 919, in full_dispatch_request
    rv = self.handle_user_exception(e)
         ^^^^^^^^^^^^^^^^^^^^^^^^^^^^^
  File "D:\research\adhd-assessment-system\backend\mlmodels\it21288326\venv\Lib\site-packages\flask_cors\extension.py", line 176, in wrapped_function
    return cors_after_request(app.make_response(f(*args, **kwargs)))
                                                ^^^^^^^^^^^^^^^^^^
  File "D:\research\adhd-assessment-system\backend\mlmodels\it21288326\venv\Lib\site-packages\flask\app.py", line 917, in full_dispatch_request
    rv = self.dispatch_request()
         ^^^^^^^^^^^^^^^^^^^^^^^
  File "D:\research\adhd-assessment-system\backend\mlmodels\it21288326\venv\Lib\site-packages\flask\app.py", line 902, in dispatch_request
    return self.ensure_sync(self.view_functions[rule.endpoint])(**view_args)  # type: ignore[no-any-return]
           ^^^^^^^^^^^^^^^^^^^^^^^^^^^^^^^^^^^^^^^^^^^^^^^^^^^^^^^^^^^^^^^^^
  File "D:\research\adhd-assessment-system\backend\mlmodels\it21288326\retrain_model.py", line 2393, in get_model_config
    "timestamp": datetime.datetime.now().isoformat()
                 ^^^^^^^^^^^^^^^^^
AttributeError: type object 'datetime.datetime' has no attribute 'datetime'
2025-03-17 14:37:53,853 - werkzeug - INFO - 127.0.0.1 - - [17/Mar/2025 14:37:53] "[35m[1mGET /api/dashboard/model-config HTTP/1.1[0m" 500 -
2025-03-17 14:37:54,126 - werkzeug - INFO - 127.0.0.1 - - [17/Mar/2025 14:37:54] "GET /api/dashboard/prediction-metrics HTTP/1.1" 200 -
2025-03-17 14:37:54,163 - __main__ - WARNING - Failed to retrieve dataset size: Collection objects do not implement truth value testing or bool(). Please compare with None instead: collection is not None
2025-03-17 14:37:54,166 - __main__ - ERROR - Error in calculate_performance_metrics_from_recent_data: Collection objects do not implement truth value testing or bool(). Please compare with None instead: collection is not None
2025-03-17 14:37:54,168 - werkzeug - INFO - 127.0.0.1 - - [17/Mar/2025 14:37:54] "GET /api/dashboard/model-metrics HTTP/1.1" 200 -
2025-03-17 14:37:54,170 - __main__ - INFO - No training_params.json file found, using default values
2025-03-17 14:37:54,172 - retrain_model - ERROR - Exception on /api/dashboard/model-config [GET]
Traceback (most recent call last):
  File "D:\research\adhd-assessment-system\backend\mlmodels\it21288326\venv\Lib\site-packages\flask\app.py", line 1511, in wsgi_app
    response = self.full_dispatch_request()
               ^^^^^^^^^^^^^^^^^^^^^^^^^^^^
  File "D:\research\adhd-assessment-system\backend\mlmodels\it21288326\venv\Lib\site-packages\flask\app.py", line 919, in full_dispatch_request
    rv = self.handle_user_exception(e)
         ^^^^^^^^^^^^^^^^^^^^^^^^^^^^^
  File "D:\research\adhd-assessment-system\backend\mlmodels\it21288326\venv\Lib\site-packages\flask_cors\extension.py", line 176, in wrapped_function
    return cors_after_request(app.make_response(f(*args, **kwargs)))
                                                ^^^^^^^^^^^^^^^^^^
  File "D:\research\adhd-assessment-system\backend\mlmodels\it21288326\venv\Lib\site-packages\flask\app.py", line 917, in full_dispatch_request
    rv = self.dispatch_request()
         ^^^^^^^^^^^^^^^^^^^^^^^
  File "D:\research\adhd-assessment-system\backend\mlmodels\it21288326\venv\Lib\site-packages\flask\app.py", line 902, in dispatch_request
    return self.ensure_sync(self.view_functions[rule.endpoint])(**view_args)  # type: ignore[no-any-return]
           ^^^^^^^^^^^^^^^^^^^^^^^^^^^^^^^^^^^^^^^^^^^^^^^^^^^^^^^^^^^^^^^^^
  File "D:\research\adhd-assessment-system\backend\mlmodels\it21288326\retrain_model.py", line 2393, in get_model_config
    "timestamp": datetime.datetime.now().isoformat()
                 ^^^^^^^^^^^^^^^^^
AttributeError: type object 'datetime.datetime' has no attribute 'datetime'
2025-03-17 14:37:54,178 - werkzeug - INFO - 127.0.0.1 - - [17/Mar/2025 14:37:54] "[35m[1mGET /api/dashboard/model-config HTTP/1.1[0m" 500 -
2025-03-17 14:37:54,184 - werkzeug - INFO - 127.0.0.1 - - [17/Mar/2025 14:37:54] "GET /api/dashboard/system-status HTTP/1.1" 200 -
2025-03-17 14:37:54,855 - werkzeug - INFO - 127.0.0.1 - - [17/Mar/2025 14:37:54] "GET /api/dashboard/assessment-stats HTTP/1.1" 200 -
2025-03-17 14:37:54,857 - werkzeug - INFO - 127.0.0.1 - - [17/Mar/2025 14:37:54] "GET /api/dashboard/prediction-metrics HTTP/1.1" 200 -
2025-03-17 14:37:56,292 - werkzeug - INFO - 127.0.0.1 - - [17/Mar/2025 14:37:56] "GET /api/dashboard/assessment-stats HTTP/1.1" 200 -
2025-03-17 14:39:04,436 - __main__ - WARNING - Failed to retrieve dataset size: Collection objects do not implement truth value testing or bool(). Please compare with None instead: collection is not None
2025-03-17 14:39:04,453 - __main__ - ERROR - Error in calculate_performance_metrics_from_recent_data: Collection objects do not implement truth value testing or bool(). Please compare with None instead: collection is not None
2025-03-17 14:39:04,453 - werkzeug - INFO - 127.0.0.1 - - [17/Mar/2025 14:39:04] "GET /api/dashboard/model-metrics HTTP/1.1" 200 -
2025-03-17 14:39:04,453 - __main__ - INFO - No training_params.json file found, using default values
2025-03-17 14:39:04,453 - retrain_model - ERROR - Exception on /api/dashboard/model-config [GET]
Traceback (most recent call last):
  File "D:\research\adhd-assessment-system\backend\mlmodels\it21288326\venv\Lib\site-packages\flask\app.py", line 1511, in wsgi_app
    response = self.full_dispatch_request()
               ^^^^^^^^^^^^^^^^^^^^^^^^^^^^
  File "D:\research\adhd-assessment-system\backend\mlmodels\it21288326\venv\Lib\site-packages\flask\app.py", line 919, in full_dispatch_request
    rv = self.handle_user_exception(e)
         ^^^^^^^^^^^^^^^^^^^^^^^^^^^^^
  File "D:\research\adhd-assessment-system\backend\mlmodels\it21288326\venv\Lib\site-packages\flask_cors\extension.py", line 176, in wrapped_function
    return cors_after_request(app.make_response(f(*args, **kwargs)))
                                                ^^^^^^^^^^^^^^^^^^
  File "D:\research\adhd-assessment-system\backend\mlmodels\it21288326\venv\Lib\site-packages\flask\app.py", line 917, in full_dispatch_request
    rv = self.dispatch_request()
         ^^^^^^^^^^^^^^^^^^^^^^^
  File "D:\research\adhd-assessment-system\backend\mlmodels\it21288326\venv\Lib\site-packages\flask\app.py", line 902, in dispatch_request
    return self.ensure_sync(self.view_functions[rule.endpoint])(**view_args)  # type: ignore[no-any-return]
           ^^^^^^^^^^^^^^^^^^^^^^^^^^^^^^^^^^^^^^^^^^^^^^^^^^^^^^^^^^^^^^^^^
  File "D:\research\adhd-assessment-system\backend\mlmodels\it21288326\retrain_model.py", line 2393, in get_model_config
    "timestamp": datetime.datetime.now().isoformat()
                 ^^^^^^^^^^^^^^^^^
AttributeError: type object 'datetime.datetime' has no attribute 'datetime'
2025-03-17 14:39:04,476 - werkzeug - INFO - 127.0.0.1 - - [17/Mar/2025 14:39:04] "[35m[1mGET /api/dashboard/model-config HTTP/1.1[0m" 500 -
2025-03-17 14:39:04,611 - werkzeug - INFO - 127.0.0.1 - - [17/Mar/2025 14:39:04] "GET /api/dashboard/system-status HTTP/1.1" 200 -
2025-03-17 14:39:04,770 - werkzeug - INFO - 127.0.0.1 - - [17/Mar/2025 14:39:04] "GET /api/dashboard/prediction-metrics HTTP/1.1" 200 -
2025-03-17 14:39:05,362 - __main__ - WARNING - Failed to retrieve dataset size: Collection objects do not implement truth value testing or bool(). Please compare with None instead: collection is not None
2025-03-17 14:39:05,362 - __main__ - ERROR - Error in calculate_performance_metrics_from_recent_data: Collection objects do not implement truth value testing or bool(). Please compare with None instead: collection is not None
2025-03-17 14:39:05,362 - __main__ - INFO - No training_params.json file found, using default values
2025-03-17 14:39:05,387 - retrain_model - ERROR - Exception on /api/dashboard/model-config [GET]
Traceback (most recent call last):
  File "D:\research\adhd-assessment-system\backend\mlmodels\it21288326\venv\Lib\site-packages\flask\app.py", line 1511, in wsgi_app
    response = self.full_dispatch_request()
               ^^^^^^^^^^^^^^^^^^^^^^^^^^^^
  File "D:\research\adhd-assessment-system\backend\mlmodels\it21288326\venv\Lib\site-packages\flask\app.py", line 919, in full_dispatch_request
    rv = self.handle_user_exception(e)
         ^^^^^^^^^^^^^^^^^^^^^^^^^^^^^
  File "D:\research\adhd-assessment-system\backend\mlmodels\it21288326\venv\Lib\site-packages\flask_cors\extension.py", line 176, in wrapped_function
    return cors_after_request(app.make_response(f(*args, **kwargs)))
                                                ^^^^^^^^^^^^^^^^^^
  File "D:\research\adhd-assessment-system\backend\mlmodels\it21288326\venv\Lib\site-packages\flask\app.py", line 917, in full_dispatch_request
    rv = self.dispatch_request()
         ^^^^^^^^^^^^^^^^^^^^^^^
  File "D:\research\adhd-assessment-system\backend\mlmodels\it21288326\venv\Lib\site-packages\flask\app.py", line 902, in dispatch_request
    return self.ensure_sync(self.view_functions[rule.endpoint])(**view_args)  # type: ignore[no-any-return]
           ^^^^^^^^^^^^^^^^^^^^^^^^^^^^^^^^^^^^^^^^^^^^^^^^^^^^^^^^^^^^^^^^^
  File "D:\research\adhd-assessment-system\backend\mlmodels\it21288326\retrain_model.py", line 2393, in get_model_config
    "timestamp": datetime.datetime.now().isoformat()
                 ^^^^^^^^^^^^^^^^^
AttributeError: type object 'datetime.datetime' has no attribute 'datetime'
2025-03-17 14:39:05,387 - werkzeug - INFO - 127.0.0.1 - - [17/Mar/2025 14:39:05] "GET /api/dashboard/model-metrics HTTP/1.1" 200 -
2025-03-17 14:39:05,393 - werkzeug - INFO - 127.0.0.1 - - [17/Mar/2025 14:39:05] "[35m[1mGET /api/dashboard/model-config HTTP/1.1[0m" 500 -
2025-03-17 14:39:05,425 - werkzeug - INFO - 127.0.0.1 - - [17/Mar/2025 14:39:05] "GET /api/dashboard/system-status HTTP/1.1" 200 -
2025-03-17 14:39:05,701 - werkzeug - INFO - 127.0.0.1 - - [17/Mar/2025 14:39:05] "GET /api/dashboard/assessment-stats HTTP/1.1" 200 -
2025-03-17 14:39:05,714 - werkzeug - INFO - 127.0.0.1 - - [17/Mar/2025 14:39:05] "GET /api/dashboard/prediction-metrics HTTP/1.1" 200 -
2025-03-17 14:39:06,161 - __main__ - WARNING - Failed to retrieve dataset size: Collection objects do not implement truth value testing or bool(). Please compare with None instead: collection is not None
2025-03-17 14:39:06,170 - __main__ - ERROR - Error in calculate_performance_metrics_from_recent_data: Collection objects do not implement truth value testing or bool(). Please compare with None instead: collection is not None
2025-03-17 14:39:06,177 - __main__ - INFO - No training_params.json file found, using default values
2025-03-17 14:39:06,179 - werkzeug - INFO - 127.0.0.1 - - [17/Mar/2025 14:39:06] "GET /api/dashboard/model-metrics HTTP/1.1" 200 -
2025-03-17 14:39:06,181 - retrain_model - ERROR - Exception on /api/dashboard/model-config [GET]
Traceback (most recent call last):
  File "D:\research\adhd-assessment-system\backend\mlmodels\it21288326\venv\Lib\site-packages\flask\app.py", line 1511, in wsgi_app
    response = self.full_dispatch_request()
               ^^^^^^^^^^^^^^^^^^^^^^^^^^^^
  File "D:\research\adhd-assessment-system\backend\mlmodels\it21288326\venv\Lib\site-packages\flask\app.py", line 919, in full_dispatch_request
    rv = self.handle_user_exception(e)
         ^^^^^^^^^^^^^^^^^^^^^^^^^^^^^
  File "D:\research\adhd-assessment-system\backend\mlmodels\it21288326\venv\Lib\site-packages\flask_cors\extension.py", line 176, in wrapped_function
    return cors_after_request(app.make_response(f(*args, **kwargs)))
                                                ^^^^^^^^^^^^^^^^^^
  File "D:\research\adhd-assessment-system\backend\mlmodels\it21288326\venv\Lib\site-packages\flask\app.py", line 917, in full_dispatch_request
    rv = self.dispatch_request()
         ^^^^^^^^^^^^^^^^^^^^^^^
  File "D:\research\adhd-assessment-system\backend\mlmodels\it21288326\venv\Lib\site-packages\flask\app.py", line 902, in dispatch_request
    return self.ensure_sync(self.view_functions[rule.endpoint])(**view_args)  # type: ignore[no-any-return]
           ^^^^^^^^^^^^^^^^^^^^^^^^^^^^^^^^^^^^^^^^^^^^^^^^^^^^^^^^^^^^^^^^^
  File "D:\research\adhd-assessment-system\backend\mlmodels\it21288326\retrain_model.py", line 2393, in get_model_config
    "timestamp": datetime.datetime.now().isoformat()
                 ^^^^^^^^^^^^^^^^^
AttributeError: type object 'datetime.datetime' has no attribute 'datetime'
2025-03-17 14:39:06,183 - werkzeug - INFO - 127.0.0.1 - - [17/Mar/2025 14:39:06] "[35m[1mGET /api/dashboard/model-config HTTP/1.1[0m" 500 -
2025-03-17 14:39:06,411 - werkzeug - INFO - 127.0.0.1 - - [17/Mar/2025 14:39:06] "GET /api/dashboard/system-status HTTP/1.1" 200 -
2025-03-17 14:39:06,491 - __main__ - WARNING - Failed to retrieve dataset size: Collection objects do not implement truth value testing or bool(). Please compare with None instead: collection is not None
2025-03-17 14:39:06,497 - __main__ - ERROR - Error in calculate_performance_metrics_from_recent_data: Collection objects do not implement truth value testing or bool(). Please compare with None instead: collection is not None
2025-03-17 14:39:06,497 - werkzeug - INFO - 127.0.0.1 - - [17/Mar/2025 14:39:06] "GET /api/dashboard/model-metrics HTTP/1.1" 200 -
2025-03-17 14:39:06,507 - __main__ - INFO - No training_params.json file found, using default values
2025-03-17 14:39:06,509 - retrain_model - ERROR - Exception on /api/dashboard/model-config [GET]
Traceback (most recent call last):
  File "D:\research\adhd-assessment-system\backend\mlmodels\it21288326\venv\Lib\site-packages\flask\app.py", line 1511, in wsgi_app
    response = self.full_dispatch_request()
               ^^^^^^^^^^^^^^^^^^^^^^^^^^^^
  File "D:\research\adhd-assessment-system\backend\mlmodels\it21288326\venv\Lib\site-packages\flask\app.py", line 919, in full_dispatch_request
    rv = self.handle_user_exception(e)
         ^^^^^^^^^^^^^^^^^^^^^^^^^^^^^
  File "D:\research\adhd-assessment-system\backend\mlmodels\it21288326\venv\Lib\site-packages\flask_cors\extension.py", line 176, in wrapped_function
    return cors_after_request(app.make_response(f(*args, **kwargs)))
                                                ^^^^^^^^^^^^^^^^^^
  File "D:\research\adhd-assessment-system\backend\mlmodels\it21288326\venv\Lib\site-packages\flask\app.py", line 917, in full_dispatch_request
    rv = self.dispatch_request()
         ^^^^^^^^^^^^^^^^^^^^^^^
  File "D:\research\adhd-assessment-system\backend\mlmodels\it21288326\venv\Lib\site-packages\flask\app.py", line 902, in dispatch_request
    return self.ensure_sync(self.view_functions[rule.endpoint])(**view_args)  # type: ignore[no-any-return]
           ^^^^^^^^^^^^^^^^^^^^^^^^^^^^^^^^^^^^^^^^^^^^^^^^^^^^^^^^^^^^^^^^^
  File "D:\research\adhd-assessment-system\backend\mlmodels\it21288326\retrain_model.py", line 2393, in get_model_config
    "timestamp": datetime.datetime.now().isoformat()
                 ^^^^^^^^^^^^^^^^^
AttributeError: type object 'datetime.datetime' has no attribute 'datetime'
2025-03-17 14:39:06,515 - werkzeug - INFO - 127.0.0.1 - - [17/Mar/2025 14:39:06] "[35m[1mGET /api/dashboard/model-config HTTP/1.1[0m" 500 -
2025-03-17 14:39:06,613 - werkzeug - INFO - 127.0.0.1 - - [17/Mar/2025 14:39:06] "GET /api/dashboard/prediction-metrics HTTP/1.1" 200 -
2025-03-17 14:39:06,808 - __main__ - WARNING - Failed to retrieve dataset size: Collection objects do not implement truth value testing or bool(). Please compare with None instead: collection is not None
2025-03-17 14:39:06,808 - __main__ - ERROR - Error in calculate_performance_metrics_from_recent_data: Collection objects do not implement truth value testing or bool(). Please compare with None instead: collection is not None
2025-03-17 14:39:06,808 - werkzeug - INFO - 127.0.0.1 - - [17/Mar/2025 14:39:06] "GET /api/dashboard/model-metrics HTTP/1.1" 200 -
2025-03-17 14:39:06,827 - __main__ - INFO - No training_params.json file found, using default values
2025-03-17 14:39:06,827 - retrain_model - ERROR - Exception on /api/dashboard/model-config [GET]
Traceback (most recent call last):
  File "D:\research\adhd-assessment-system\backend\mlmodels\it21288326\venv\Lib\site-packages\flask\app.py", line 1511, in wsgi_app
    response = self.full_dispatch_request()
               ^^^^^^^^^^^^^^^^^^^^^^^^^^^^
  File "D:\research\adhd-assessment-system\backend\mlmodels\it21288326\venv\Lib\site-packages\flask\app.py", line 919, in full_dispatch_request
    rv = self.handle_user_exception(e)
         ^^^^^^^^^^^^^^^^^^^^^^^^^^^^^
  File "D:\research\adhd-assessment-system\backend\mlmodels\it21288326\venv\Lib\site-packages\flask_cors\extension.py", line 176, in wrapped_function
    return cors_after_request(app.make_response(f(*args, **kwargs)))
                                                ^^^^^^^^^^^^^^^^^^
  File "D:\research\adhd-assessment-system\backend\mlmodels\it21288326\venv\Lib\site-packages\flask\app.py", line 917, in full_dispatch_request
    rv = self.dispatch_request()
         ^^^^^^^^^^^^^^^^^^^^^^^
  File "D:\research\adhd-assessment-system\backend\mlmodels\it21288326\venv\Lib\site-packages\flask\app.py", line 902, in dispatch_request
    return self.ensure_sync(self.view_functions[rule.endpoint])(**view_args)  # type: ignore[no-any-return]
           ^^^^^^^^^^^^^^^^^^^^^^^^^^^^^^^^^^^^^^^^^^^^^^^^^^^^^^^^^^^^^^^^^
  File "D:\research\adhd-assessment-system\backend\mlmodels\it21288326\retrain_model.py", line 2393, in get_model_config
    "timestamp": datetime.datetime.now().isoformat()
                 ^^^^^^^^^^^^^^^^^
AttributeError: type object 'datetime.datetime' has no attribute 'datetime'
2025-03-17 14:39:06,834 - werkzeug - INFO - 127.0.0.1 - - [17/Mar/2025 14:39:06] "[35m[1mGET /api/dashboard/model-config HTTP/1.1[0m" 500 -
2025-03-17 14:39:06,927 - werkzeug - INFO - 127.0.0.1 - - [17/Mar/2025 14:39:06] "GET /api/dashboard/system-status HTTP/1.1" 200 -
2025-03-17 14:39:07,028 - werkzeug - INFO - 127.0.0.1 - - [17/Mar/2025 14:39:07] "GET /api/dashboard/assessment-stats HTTP/1.1" 200 -
2025-03-17 14:39:07,126 - __main__ - WARNING - Failed to retrieve dataset size: Collection objects do not implement truth value testing or bool(). Please compare with None instead: collection is not None
2025-03-17 14:39:07,126 - __main__ - ERROR - Error in calculate_performance_metrics_from_recent_data: Collection objects do not implement truth value testing or bool(). Please compare with None instead: collection is not None
2025-03-17 14:39:07,126 - werkzeug - INFO - 127.0.0.1 - - [17/Mar/2025 14:39:07] "GET /api/dashboard/model-metrics HTTP/1.1" 200 -
2025-03-17 14:39:07,147 - __main__ - INFO - No training_params.json file found, using default values
2025-03-17 14:39:07,147 - retrain_model - ERROR - Exception on /api/dashboard/model-config [GET]
Traceback (most recent call last):
  File "D:\research\adhd-assessment-system\backend\mlmodels\it21288326\venv\Lib\site-packages\flask\app.py", line 1511, in wsgi_app
    response = self.full_dispatch_request()
               ^^^^^^^^^^^^^^^^^^^^^^^^^^^^
  File "D:\research\adhd-assessment-system\backend\mlmodels\it21288326\venv\Lib\site-packages\flask\app.py", line 919, in full_dispatch_request
    rv = self.handle_user_exception(e)
         ^^^^^^^^^^^^^^^^^^^^^^^^^^^^^
  File "D:\research\adhd-assessment-system\backend\mlmodels\it21288326\venv\Lib\site-packages\flask_cors\extension.py", line 176, in wrapped_function
    return cors_after_request(app.make_response(f(*args, **kwargs)))
                                                ^^^^^^^^^^^^^^^^^^
  File "D:\research\adhd-assessment-system\backend\mlmodels\it21288326\venv\Lib\site-packages\flask\app.py", line 917, in full_dispatch_request
    rv = self.dispatch_request()
         ^^^^^^^^^^^^^^^^^^^^^^^
  File "D:\research\adhd-assessment-system\backend\mlmodels\it21288326\venv\Lib\site-packages\flask\app.py", line 902, in dispatch_request
    return self.ensure_sync(self.view_functions[rule.endpoint])(**view_args)  # type: ignore[no-any-return]
           ^^^^^^^^^^^^^^^^^^^^^^^^^^^^^^^^^^^^^^^^^^^^^^^^^^^^^^^^^^^^^^^^^
  File "D:\research\adhd-assessment-system\backend\mlmodels\it21288326\retrain_model.py", line 2393, in get_model_config
    "timestamp": datetime.datetime.now().isoformat()
                 ^^^^^^^^^^^^^^^^^
AttributeError: type object 'datetime.datetime' has no attribute 'datetime'
2025-03-17 14:39:07,147 - werkzeug - INFO - 127.0.0.1 - - [17/Mar/2025 14:39:07] "[35m[1mGET /api/dashboard/model-config HTTP/1.1[0m" 500 -
2025-03-17 14:39:07,222 - werkzeug - INFO - 127.0.0.1 - - [17/Mar/2025 14:39:07] "GET /api/dashboard/prediction-metrics HTTP/1.1" 200 -
2025-03-17 14:39:07,380 - werkzeug - INFO - 127.0.0.1 - - [17/Mar/2025 14:39:07] "GET /api/dashboard/system-status HTTP/1.1" 200 -
2025-03-17 14:39:07,444 - __main__ - WARNING - Failed to retrieve dataset size: Collection objects do not implement truth value testing or bool(). Please compare with None instead: collection is not None
2025-03-17 14:39:07,450 - __main__ - ERROR - Error in calculate_performance_metrics_from_recent_data: Collection objects do not implement truth value testing or bool(). Please compare with None instead: collection is not None
2025-03-17 14:39:07,453 - werkzeug - INFO - 127.0.0.1 - - [17/Mar/2025 14:39:07] "GET /api/dashboard/model-metrics HTTP/1.1" 200 -
2025-03-17 14:39:07,460 - __main__ - INFO - No training_params.json file found, using default values
2025-03-17 14:39:07,465 - retrain_model - ERROR - Exception on /api/dashboard/model-config [GET]
Traceback (most recent call last):
  File "D:\research\adhd-assessment-system\backend\mlmodels\it21288326\venv\Lib\site-packages\flask\app.py", line 1511, in wsgi_app
    response = self.full_dispatch_request()
               ^^^^^^^^^^^^^^^^^^^^^^^^^^^^
  File "D:\research\adhd-assessment-system\backend\mlmodels\it21288326\venv\Lib\site-packages\flask\app.py", line 919, in full_dispatch_request
    rv = self.handle_user_exception(e)
         ^^^^^^^^^^^^^^^^^^^^^^^^^^^^^
  File "D:\research\adhd-assessment-system\backend\mlmodels\it21288326\venv\Lib\site-packages\flask_cors\extension.py", line 176, in wrapped_function
    return cors_after_request(app.make_response(f(*args, **kwargs)))
                                                ^^^^^^^^^^^^^^^^^^
  File "D:\research\adhd-assessment-system\backend\mlmodels\it21288326\venv\Lib\site-packages\flask\app.py", line 917, in full_dispatch_request
    rv = self.dispatch_request()
         ^^^^^^^^^^^^^^^^^^^^^^^
  File "D:\research\adhd-assessment-system\backend\mlmodels\it21288326\venv\Lib\site-packages\flask\app.py", line 902, in dispatch_request
    return self.ensure_sync(self.view_functions[rule.endpoint])(**view_args)  # type: ignore[no-any-return]
           ^^^^^^^^^^^^^^^^^^^^^^^^^^^^^^^^^^^^^^^^^^^^^^^^^^^^^^^^^^^^^^^^^
  File "D:\research\adhd-assessment-system\backend\mlmodels\it21288326\retrain_model.py", line 2393, in get_model_config
    "timestamp": datetime.datetime.now().isoformat()
                 ^^^^^^^^^^^^^^^^^
AttributeError: type object 'datetime.datetime' has no attribute 'datetime'
2025-03-17 14:39:07,469 - werkzeug - INFO - 127.0.0.1 - - [17/Mar/2025 14:39:07] "[35m[1mGET /api/dashboard/model-config HTTP/1.1[0m" 500 -
2025-03-17 14:39:07,920 - werkzeug - INFO - 127.0.0.1 - - [17/Mar/2025 14:39:07] "GET /api/dashboard/prediction-metrics HTTP/1.1" 200 -
2025-03-17 14:39:07,956 - werkzeug - INFO - 127.0.0.1 - - [17/Mar/2025 14:39:07] "GET /api/dashboard/system-status HTTP/1.1" 200 -
2025-03-17 14:39:08,684 - werkzeug - INFO - 127.0.0.1 - - [17/Mar/2025 14:39:08] "GET /api/dashboard/assessment-stats HTTP/1.1" 200 -
2025-03-17 14:39:08,748 - werkzeug - INFO - 127.0.0.1 - - [17/Mar/2025 14:39:08] "GET /api/dashboard/system-status HTTP/1.1" 200 -
2025-03-17 14:39:08,827 - werkzeug - INFO - 127.0.0.1 - - [17/Mar/2025 14:39:08] "GET /api/dashboard/prediction-metrics HTTP/1.1" 200 -
2025-03-17 14:39:09,758 - werkzeug - INFO - 127.0.0.1 - - [17/Mar/2025 14:39:09] "GET /api/dashboard/prediction-metrics HTTP/1.1" 200 -
2025-03-17 14:39:10,201 - werkzeug - INFO - 127.0.0.1 - - [17/Mar/2025 14:39:10] "GET /api/dashboard/assessment-stats HTTP/1.1" 200 -
2025-03-17 14:39:11,633 - werkzeug - INFO - 127.0.0.1 - - [17/Mar/2025 14:39:11] "GET /api/dashboard/assessment-stats HTTP/1.1" 200 -
2025-03-17 14:39:13,184 - werkzeug - INFO - 127.0.0.1 - - [17/Mar/2025 14:39:13] "GET /api/dashboard/assessment-stats HTTP/1.1" 200 -
2025-03-17 14:39:14,825 - werkzeug - INFO - 127.0.0.1 - - [17/Mar/2025 14:39:14] "GET /api/dashboard/assessment-stats HTTP/1.1" 200 -
2025-03-17 14:40:38,654 - __main__ - WARNING - Failed to retrieve dataset size: Collection objects do not implement truth value testing or bool(). Please compare with None instead: collection is not None
2025-03-17 14:40:38,654 - __main__ - ERROR - Error in calculate_performance_metrics_from_recent_data: Collection objects do not implement truth value testing or bool(). Please compare with None instead: collection is not None
2025-03-17 14:40:38,670 - werkzeug - INFO - 127.0.0.1 - - [17/Mar/2025 14:40:38] "GET /api/dashboard/model-metrics HTTP/1.1" 200 -
2025-03-17 14:40:38,670 - __main__ - INFO - No training_params.json file found, using default values
2025-03-17 14:40:38,670 - retrain_model - ERROR - Exception on /api/dashboard/model-config [GET]
Traceback (most recent call last):
  File "D:\research\adhd-assessment-system\backend\mlmodels\it21288326\venv\Lib\site-packages\flask\app.py", line 1511, in wsgi_app
    response = self.full_dispatch_request()
               ^^^^^^^^^^^^^^^^^^^^^^^^^^^^
  File "D:\research\adhd-assessment-system\backend\mlmodels\it21288326\venv\Lib\site-packages\flask\app.py", line 919, in full_dispatch_request
    rv = self.handle_user_exception(e)
         ^^^^^^^^^^^^^^^^^^^^^^^^^^^^^
  File "D:\research\adhd-assessment-system\backend\mlmodels\it21288326\venv\Lib\site-packages\flask_cors\extension.py", line 176, in wrapped_function
    return cors_after_request(app.make_response(f(*args, **kwargs)))
                                                ^^^^^^^^^^^^^^^^^^
  File "D:\research\adhd-assessment-system\backend\mlmodels\it21288326\venv\Lib\site-packages\flask\app.py", line 917, in full_dispatch_request
    rv = self.dispatch_request()
         ^^^^^^^^^^^^^^^^^^^^^^^
  File "D:\research\adhd-assessment-system\backend\mlmodels\it21288326\venv\Lib\site-packages\flask\app.py", line 902, in dispatch_request
    return self.ensure_sync(self.view_functions[rule.endpoint])(**view_args)  # type: ignore[no-any-return]
           ^^^^^^^^^^^^^^^^^^^^^^^^^^^^^^^^^^^^^^^^^^^^^^^^^^^^^^^^^^^^^^^^^
  File "D:\research\adhd-assessment-system\backend\mlmodels\it21288326\retrain_model.py", line 2393, in get_model_config
    "timestamp": datetime.datetime.now().isoformat()
                 ^^^^^^^^^^^^^^^^^
AttributeError: type object 'datetime.datetime' has no attribute 'datetime'
2025-03-17 14:40:38,691 - werkzeug - INFO - 127.0.0.1 - - [17/Mar/2025 14:40:38] "[35m[1mGET /api/dashboard/model-config HTTP/1.1[0m" 500 -
2025-03-17 14:40:38,857 - werkzeug - INFO - 127.0.0.1 - - [17/Mar/2025 14:40:38] "GET /api/dashboard/system-status HTTP/1.1" 200 -
2025-03-17 14:40:38,893 - __main__ - WARNING - Failed to retrieve dataset size: Collection objects do not implement truth value testing or bool(). Please compare with None instead: collection is not None
2025-03-17 14:40:38,893 - __main__ - ERROR - Error in calculate_performance_metrics_from_recent_data: Collection objects do not implement truth value testing or bool(). Please compare with None instead: collection is not None
2025-03-17 14:40:38,893 - werkzeug - INFO - 127.0.0.1 - - [17/Mar/2025 14:40:38] "GET /api/dashboard/model-metrics HTTP/1.1" 200 -
2025-03-17 14:40:39,005 - __main__ - INFO - No training_params.json file found, using default values
2025-03-17 14:40:39,005 - retrain_model - ERROR - Exception on /api/dashboard/model-config [GET]
Traceback (most recent call last):
  File "D:\research\adhd-assessment-system\backend\mlmodels\it21288326\venv\Lib\site-packages\flask\app.py", line 1511, in wsgi_app
    response = self.full_dispatch_request()
               ^^^^^^^^^^^^^^^^^^^^^^^^^^^^
  File "D:\research\adhd-assessment-system\backend\mlmodels\it21288326\venv\Lib\site-packages\flask\app.py", line 919, in full_dispatch_request
    rv = self.handle_user_exception(e)
         ^^^^^^^^^^^^^^^^^^^^^^^^^^^^^
  File "D:\research\adhd-assessment-system\backend\mlmodels\it21288326\venv\Lib\site-packages\flask_cors\extension.py", line 176, in wrapped_function
    return cors_after_request(app.make_response(f(*args, **kwargs)))
                                                ^^^^^^^^^^^^^^^^^^
  File "D:\research\adhd-assessment-system\backend\mlmodels\it21288326\venv\Lib\site-packages\flask\app.py", line 917, in full_dispatch_request
    rv = self.dispatch_request()
         ^^^^^^^^^^^^^^^^^^^^^^^
  File "D:\research\adhd-assessment-system\backend\mlmodels\it21288326\venv\Lib\site-packages\flask\app.py", line 902, in dispatch_request
    return self.ensure_sync(self.view_functions[rule.endpoint])(**view_args)  # type: ignore[no-any-return]
           ^^^^^^^^^^^^^^^^^^^^^^^^^^^^^^^^^^^^^^^^^^^^^^^^^^^^^^^^^^^^^^^^^
  File "D:\research\adhd-assessment-system\backend\mlmodels\it21288326\retrain_model.py", line 2393, in get_model_config
    "timestamp": datetime.datetime.now().isoformat()
                 ^^^^^^^^^^^^^^^^^
AttributeError: type object 'datetime.datetime' has no attribute 'datetime'
2025-03-17 14:40:39,005 - werkzeug - INFO - 127.0.0.1 - - [17/Mar/2025 14:40:39] "[35m[1mGET /api/dashboard/model-config HTTP/1.1[0m" 500 -
2025-03-17 14:40:39,044 - werkzeug - INFO - 127.0.0.1 - - [17/Mar/2025 14:40:39] "GET /api/dashboard/prediction-metrics HTTP/1.1" 200 -
2025-03-17 14:40:39,381 - werkzeug - INFO - 127.0.0.1 - - [17/Mar/2025 14:40:39] "GET /api/dashboard/system-status HTTP/1.1" 200 -
2025-03-17 14:40:39,753 - werkzeug - INFO - 127.0.0.1 - - [17/Mar/2025 14:40:39] "GET /api/dashboard/assessment-stats HTTP/1.1" 200 -
2025-03-17 14:40:39,753 - werkzeug - INFO - 127.0.0.1 - - [17/Mar/2025 14:40:39] "GET /api/dashboard/prediction-metrics HTTP/1.1" 200 -
2025-03-17 14:40:41,401 - werkzeug - INFO - 127.0.0.1 - - [17/Mar/2025 14:40:41] "GET /api/dashboard/assessment-stats HTTP/1.1" 200 -
2025-03-17 14:41:10,483 - __main__ - INFO - MongoDB connection established successfully
2025-03-17 14:41:10,679 - __main__ - INFO - Model loaded successfully
2025-03-17 14:41:10,679 - __main__ - INFO - Scaler loaded successfully
2025-03-17 14:41:10,683 - __main__ - INFO - Label encoder loaded successfully
2025-03-17 14:41:10,686 - __main__ - INFO - Starting prediction service on http://localhost:5000
2025-03-17 14:41:10,691 - werkzeug - INFO - [31m[1mWARNING: This is a development server. Do not use it in a production deployment. Use a production WSGI server instead.[0m
 * Running on all addresses (0.0.0.0)
 * Running on http://127.0.0.1:5000
 * Running on http://172.28.4.140:5000
2025-03-17 14:41:10,699 - werkzeug - INFO - [33mPress CTRL+C to quit[0m
2025-03-17 14:41:22,135 - __main__ - WARNING - Failed to retrieve dataset size: Collection objects do not implement truth value testing or bool(). Please compare with None instead: collection is not None
2025-03-17 14:41:22,149 - __main__ - ERROR - Error in calculate_performance_metrics_from_recent_data: Collection objects do not implement truth value testing or bool(). Please compare with None instead: collection is not None
2025-03-17 14:41:22,149 - werkzeug - INFO - 127.0.0.1 - - [17/Mar/2025 14:41:22] "GET /api/dashboard/model-metrics HTTP/1.1" 200 -
2025-03-17 14:41:22,158 - __main__ - INFO - No training_params.json file found, using default values
2025-03-17 14:41:22,165 - retrain_model - ERROR - Exception on /api/dashboard/model-config [GET]
Traceback (most recent call last):
  File "D:\research\adhd-assessment-system\backend\mlmodels\it21288326\venv\Lib\site-packages\flask\app.py", line 1511, in wsgi_app
    response = self.full_dispatch_request()
               ^^^^^^^^^^^^^^^^^^^^^^^^^^^^
  File "D:\research\adhd-assessment-system\backend\mlmodels\it21288326\venv\Lib\site-packages\flask\app.py", line 919, in full_dispatch_request
    rv = self.handle_user_exception(e)
         ^^^^^^^^^^^^^^^^^^^^^^^^^^^^^
  File "D:\research\adhd-assessment-system\backend\mlmodels\it21288326\venv\Lib\site-packages\flask_cors\extension.py", line 176, in wrapped_function
    return cors_after_request(app.make_response(f(*args, **kwargs)))
                                                ^^^^^^^^^^^^^^^^^^
  File "D:\research\adhd-assessment-system\backend\mlmodels\it21288326\venv\Lib\site-packages\flask\app.py", line 917, in full_dispatch_request
    rv = self.dispatch_request()
         ^^^^^^^^^^^^^^^^^^^^^^^
  File "D:\research\adhd-assessment-system\backend\mlmodels\it21288326\venv\Lib\site-packages\flask\app.py", line 902, in dispatch_request
    return self.ensure_sync(self.view_functions[rule.endpoint])(**view_args)  # type: ignore[no-any-return]
           ^^^^^^^^^^^^^^^^^^^^^^^^^^^^^^^^^^^^^^^^^^^^^^^^^^^^^^^^^^^^^^^^^
  File "D:\research\adhd-assessment-system\backend\mlmodels\it21288326\retrain_model.py", line 2393, in get_model_config
    "timestamp": datetime.datetime.now().isoformat()
                 ^^^^^^^^^^^^^^^^^
AttributeError: type object 'datetime.datetime' has no attribute 'datetime'
2025-03-17 14:41:22,180 - werkzeug - INFO - 127.0.0.1 - - [17/Mar/2025 14:41:22] "[35m[1mGET /api/dashboard/model-config HTTP/1.1[0m" 500 -
2025-03-17 14:41:22,539 - werkzeug - INFO - 127.0.0.1 - - [17/Mar/2025 14:41:22] "GET /api/dashboard/system-status HTTP/1.1" 200 -
2025-03-17 14:41:24,106 - werkzeug - INFO - 127.0.0.1 - - [17/Mar/2025 14:41:24] "GET /api/dashboard/prediction-metrics HTTP/1.1" 200 -
2025-03-17 14:41:24,632 - werkzeug - INFO - 127.0.0.1 - - [17/Mar/2025 14:41:24] "GET /api/dashboard/assessment-stats HTTP/1.1" 200 -
2025-03-17 15:06:13,425 - __main__ - INFO - MongoDB connection established successfully
2025-03-17 15:06:13,808 - __main__ - INFO - Model loaded successfully
2025-03-17 15:06:13,808 - __main__ - INFO - Scaler loaded successfully
2025-03-17 15:06:13,808 - __main__ - INFO - Label encoder loaded successfully
2025-03-17 15:06:13,821 - __main__ - INFO - Starting prediction service on http://localhost:5000
2025-03-17 15:06:13,844 - werkzeug - INFO - [31m[1mWARNING: This is a development server. Do not use it in a production deployment. Use a production WSGI server instead.[0m
 * Running on all addresses (0.0.0.0)
 * Running on http://127.0.0.1:5000
 * Running on http://172.28.4.140:5000
2025-03-17 15:06:13,844 - werkzeug - INFO - [33mPress CTRL+C to quit[0m
2025-03-17 15:09:19,387 - werkzeug - INFO - 127.0.0.1 - - [17/Mar/2025 15:09:19] "GET /health HTTP/1.1" 200 -
2025-03-17 15:09:19,623 - werkzeug - INFO - 127.0.0.1 - - [17/Mar/2025 15:09:19] "GET /health HTTP/1.1" 200 -
